Workbook

Sheet BT Estimate
A1: Category | B1: Cost Code | C1: Title | D1: Cost Type | E1: Unit Cost | F1: Quantity | G1: Unit | H1: Builder Cost | I1: Markup | J1: Owner Cost | K1: Mobilization | L1: New Value | M1: Source / Link
A2: 00 - General Conditions | B2: 001 - Supervision | C2: Site Supervision | D2: Allowance | E2: 18000 | F2: 4 | G2: Months | H2: =E2*F2 -> 72000 | I2: 0.2 | J2: =H2*(1+I2) -> 86400 | K2: =J2*3% -> 2592 | L2: =J2-K2 -> 83808 | M2: Qty: package/derived • Rate from Buyout [001]
A3: 00 - General Conditions | B3: 004 - Site Office | C3: Site Office | D3: Allowance | E3: 1500 | F3: 4 | G3: Months | H3: =E3*F3 -> 6000 | I3: 0.2 | J3: =H3*(1+I3) -> 7200 | K3: =J3*3% -> 216 | L3: =J3-K3 -> 6984 | M3: Qty: package/derived • Rate from Buyout [004]
A4: 00 - General Conditions | B4: 005 - Housing | C4: Housing - Management | D4: Allowance | E4: 15000 | F4: 4 | G4: Months | H4: =E4*F4 -> 60000 | I4: 0.2 | J4: =H4*(1+I4) -> 72000 | K4: =J4*3% -> 2160 | L4: =J4-K4 -> 69840 | M4: Qty: package/derived • Rate from Buyout [005]
A5: 00 - General Conditions | B5: 006 - Forklift | C5: Forklift | D5: Equipment | E5: 8000 | F5: 4 | G5: Months | H5: =E5*F5 -> 32000 | I5: 0.2 | J5: =H5*(1+I5) -> 38400 | K5: =J5*3% -> 1152 | L5: =J5-K5 -> 37248 | M5: Qty: package/derived • Rate from Buyout [006]
A6: 00 - General Conditions | B6: 007 - Manlift | C6: Manlift | D6: Equipment | E6: 7000 | F6: 4 | G6: Months | H6: =E6*F6 -> 28000 | I6: 0.2 | J6: =H6*(1+I6) -> 33600 | K6: =J6*3% -> 1008 | L6: =J6-K6 -> 32592 | M6: Qty: package/derived • Rate from Buyout [007]
A7: 00 - General Conditions | B7: 008 - Crane | C7: Crane | D7: Equipment | E7: 50000 | F7: 1 | G7: SF | H7: =E7*F7 -> 50000 | I7: 0.2 | J7: =H7*(1+I7) -> 60000 | K7: =J7*3% -> 1800 | L7: =J7-K7 -> 58200 | M7: Qty: package/derived • Rate from Buyout [008]
A8: 00 - General Conditions | B8: 013 - Fuel | C8: Fuel | D8: Allowance | E8: 1750 | F8: 4 | G8: Months | H8: =E8*F8 -> 7000 | I8: 0.2 | J8: =H8*(1+I8) -> 8400 | K8: =J8*3% -> 252 | L8: =J8-K8 -> 8148 | M8: Qty: package/derived • Rate from Buyout [013]
A9: 01 - Framing | B9: 101 - Layout - Labor | C9: Building I Layout - BLDG 1 | D9: Labor | E9: 0.25 | F9: ='SRC-Estimate'!C30 -> 25197 | G9: SF | H9: =E9*F9 -> 6299.25 | I9: 1.8 | J9: =H9*(1+I9) -> 17637.9 | K9: =J9*3% -> 529.137 | L9: =J9-K9 -> 17108.763 | M9: Qty ='SRC-Estimate'!C30 • Rate from Buyout [101]
A10: 01 - Framing | B10: 101 - Layout - Labor | C10: Building II Layout - BLDG 1 | D10: Labor | E10: 0.25 | F10: ='SRC-Estimate'!I30 -> 25375 | G10: SF | H10: =E10*F10 -> 6343.75 | I10: 1.8 | J10: =H10*(1+I10) -> 17762.5 | K10: =J10*3% -> 532.875 | L10: =J10-K10 -> 17229.625 | M10: Qty ='SRC-Estimate'!I30 • Rate from Buyout [101]
A11: 01 - Framing | B11: 102 - Framing - Labor | C11: Building I Wall Framing - BLDG 1 | D11: Labor | E11: 1.1 | F11: ='SRC-Estimate'!C30 -> 25197 | G11: SF | H11: =E11*F11 -> 27716.7 | I11: 1.5 | J11: =H11*(1+I11) -> 69291.75 | K11: =J11*3% -> 2078.7525 | L11: =J11-K11 -> 67212.997 | M11: Qty ='SRC-Estimate'!C30 • Rate from Buyout [102]
A12: 01 - Framing | B12: 102 - Framing - Labor | C12: Building II Wall Framing - BLDG 1 | D12: Labor | E12: 1.1 | F12: ='SRC-Estimate'!I30 -> 25375 | G12: SF | H12: =E12*F12 -> 27912.5 | I12: 1.5 | J12: =H12*(1+I12) -> 69781.25 | K12: =J12*3% -> 2093.4375 | L12: =J12-K12 -> 67687.813 | M12: Qty ='SRC-Estimate'!I30 • Rate from Buyout [102]
A13: 01 - Framing | B13: 103 - Sheathing - Labor | C13: Building I Sheathing - BLDG 1 | D13: Labor | E13: 0.25 | F13: ='SRC-Estimate'!C30 -> 25197 | G13: SF | H13: =E13*F13 -> 6299.25 | I13: 1.2 | J13: =H13*(1+I13) -> 13858.35 | K13: =J13*3% -> 415.7505 | L13: =J13-K13 -> 13442.6 | M13: Qty ='SRC-Estimate'!C30 • Rate from Buyout [103]
A14: 01 - Framing | B14: 103 - Sheathing - Labor | C14: Building II Sheathing - BLDG 1 | D14: Labor | E14: 0.25 | F14: ='SRC-Estimate'!I30 -> 25375 | G14: SF | H14: =E14*F14 -> 6343.75 | I14: 1.2 | J14: =H14*(1+I14) -> 13956.25 | K14: =J14*3% -> 418.6875 | L14: =J14-K14 -> 13537.563 | M14: Qty ='SRC-Estimate'!I30 • Rate from Buyout [103]
A15: 01 - Framing | B15: 109 - Hardware - Labor | C15: Building I Hardware - BLDG 1 | D15: Labor | E15: 0.25 | F15: ='SRC-Estimate'!C30 -> 25197 | G15: SF | H15: =E15*F15 -> 6299.25 | I15: 0.75 | J15: =H15*(1+I15) -> 11023.688 | K15: =J15*3% -> 330.71062 | L15: =J15-K15 -> 10692.977 | M15: Qty ='SRC-Estimate'!C30 • Rate from Buyout [109]
A16: 01 - Framing | B16: 109 - Hardware - Labor | C16: Building II Hardware - BLDG 1 | D16: Labor | E16: 0.25 | F16: ='SRC-Estimate'!I30 -> 25375 | G16: SF | H16: =E16*F16 -> 6343.75 | I16: 0.75 | J16: =H16*(1+I16) -> 11101.562 | K16: =J16*3% -> 333.04688 | L16: =J16-K16 -> 10768.516 | M16: Qty ='SRC-Estimate'!I30 • Rate from Buyout [109]
A17: 01 - Framing | B17: 115 - Punchout - Labor | C17: Building I Punchout - BLDG 1 | D17: Labor | E17: 0.2 | F17: ='SRC-Estimate'!C30 -> 25197 | G17: SF | H17: =E17*F17 -> 5039.4 | I17: 0.6 | J17: =H17*(1+I17) -> 8063.04 | K17: =J17*3% -> 241.8912 | L17: =J17-K17 -> 7821.1488 | M17: Qty ='SRC-Estimate'!C30 • Rate from Buyout [115]
A18: 01 - Framing | B18: 115 - Punchout - Labor | C18: Building II Punchout - BLDG 1 | D18: Labor | E18: 0.2 | F18: ='SRC-Estimate'!I30 -> 25375 | G18: SF | H18: =E18*F18 -> 5075 | I18: 0.6 | J18: =H18*(1+I18) -> 8120 | K18: =J18*3% -> 243.6 | L18: =J18-K18 -> 7876.4 | M18: Qty ='SRC-Estimate'!I30 • Rate from Buyout [115]
A19: 01 - Framing | B19: 206 - Nails - Framing | C19: Nails Framing | D19: Labor | E19: 0.65 | F19: 50572 | G19: SF | H19: =E19*F19 -> 32871.8 | I19: =(J19/H19)-1 -> 43.74028 | J19: =2017289.812-SUM(J2:J18) -> 1470693.5 | K19: =J19*3% -> 44120.806 | L19: =J19-K19 -> 1426572.7 | M19: Nails PLUG = contract − SUM(owner above) • Rate from Buyout [206]
A20: 01 - Framing | B20: 201 - Lumber - Material | C20: Building I Lumber Package - BLDG 1 | D20: Material | E20: 29.661 | F20: 25197 | G20: SF | H20: =E20*F20 -> 747368.22 | I20: 0.3667 | J20: =H20*(1+I20) -> 1021428.1 | K20: =J20*3% -> 30642.844 | L20: =J20-K20 -> 990785.3 | M20: Qty: package/derived • Rate from Buyout [201]
A21: 01 - Framing | B21: 201 - Lumber - Material | C21: Building II Lumber Package - BLDG 1 | D21: Material | E21: 29.661 | F21: 25375 | G21: SF | H21: =E21*F21 -> 752647.88 | I21: 0.3667 | J21: =H21*(1+I21) -> 1028643.9 | K21: =J21*3% -> 30859.316 | L21: =J21-K21 -> 997784.54 | M21: Qty: package/derived • Rate from Buyout [201]
A22: 01 - Framing | B22: 205 - Hardware - Material | C22: Building I Hardware Package - BLDG 1 | D22: Material | E22: 3.164 | F22: 25197 | G22: SF | H22: =E22*F22 -> 79723.308 | I22: 0.1562 | J22: =H22*(1+I22) -> 92176.089 | K22: =J22*3% -> 2765.2827 | L22: =J22-K22 -> 89410.806 | M22: Qty: package/derived • Rate from Buyout [205]
A23: 01 - Framing | B23: 205 - Hardware - Material | C23: Building II Hardware Package - BLDG 1 | D23: Material | E23: 3.164 | F23: 25375 | G23: SF | H23: =E23*F23 -> 80286.5 | I23: 0.1562 | J23: =H23*(1+I23) -> 92827.251 | K23: =J23*3% -> 2784.8175 | L23: =J23-K23 -> 90042.434 | M23: Qty: package/derived • Rate from Buyout [205]
A24: 01 - Framing | B24: 207 - Trusses - Material | C24: Building I Truss Package - BLDG 1 | D24: Material | E24: 13.486 | F24: 25197 | G24: SF | H24: =E24*F24 -> 339806.74 | I24: 0.1804 | J24: =H24*(1+I24) -> 401107.88 | K24: =J24*3% -> 12033.236 | L24: =J24-K24 -> 389074.64 | M24: Qty: package/derived • Rate from Buyout [207]
A25: 01 - Framing | B25: 207 - Trusses - Material | C25: Building II Truss Package - BLDG 1 | D25: Material | E25: 13.486 | F25: 25375 | G25: SF | H25: =E25*F25 -> 342207.25 | I25: 0.1804 | J25: =H25*(1+I25) -> 403941.44 | K25: =J25*3% -> 12118.243 | L25: =J25-K25 -> 391823.19 | M25: Qty: package/derived • Rate from Buyout [207]

Sheet SOV
A1: Owners Invoices | F1: Dist/line: | G1: 107712.04
A2: # | B2: Scope | C2: Type | D2: Value
A3: 1 | B3: Mobilization | D3: =SUM('BT Estimate'!K2:K25) -> 151722.43
A4: 2 | B4: Building I Layout - BLDG 1 | C4: Labor | D4: =VLOOKUP(B4,'BT Estimate'!C:L,10,FALSE)+$G$1 -> 124820.81
A5: 3 | B5: Building II Layout - BLDG 1 | C5: Labor | D5: =VLOOKUP(B5,'BT Estimate'!C:L,10,FALSE)+$G$1 -> 124941.67
A6: 4 | B6: Building I Wall Framing - BLDG 1 | C6: Labor | D6: =VLOOKUP(B6,'BT Estimate'!C:L,10,FALSE)+$G$1 -> 174925.04
A7: 5 | B7: Building II Wall Framing - BLDG 1 | C7: Labor | D7: =VLOOKUP(B7,'BT Estimate'!C:L,10,FALSE)+$G$1 -> 175399.86
A8: 6 | B8: Building I Sheathing - BLDG 1 | C8: Labor | D8: =VLOOKUP(B8,'BT Estimate'!C:L,10,FALSE)+$G$1 -> 121154.64
A9: 7 | B9: Building II Sheathing - BLDG 1 | C9: Labor | D9: =VLOOKUP(B9,'BT Estimate'!C:L,10,FALSE)+$G$1 -> 121249.61
A10: 8 | B10: Building I Hardware - BLDG 1 | C10: Labor | D10: =VLOOKUP(B10,'BT Estimate'!C:L,10,FALSE)+$G$1 -> 118405.02
A11: 9 | B11: Building II Hardware - BLDG 1 | C11: Labor | D11: =VLOOKUP(B11,'BT Estimate'!C:L,10,FALSE)+$G$1 -> 118480.56
A12: 10 | B12: Building I Punchout - BLDG 1 | C12: Labor | D12: =VLOOKUP(B12,'BT Estimate'!C:L,10,FALSE)+$G$1 -> 115533.19
A13: 11 | B13: Building II Punchout - BLDG 1 | C13: Labor | D13: =VLOOKUP(B13,'BT Estimate'!C:L,10,FALSE)+$G$1 -> 115588.44
A14: 12 | B14: Building I Lumber Package - BLDG 1 | C14: Material | D14: =VLOOKUP(B14,'BT Estimate'!C:L,10,FALSE)+$G$1 -> 1098497.3
A15: 13 | B15: Building II Lumber Package - BLDG 1 | C15: Material | D15: =VLOOKUP(B15,'BT Estimate'!C:L,10,FALSE)+$G$1 -> 1105496.6
... A19: 17 | B19: Building II Truss Package - BLDG 1 | C19: Material | D19: =VLOOKUP(B19,'BT Estimate'!C:L,10,FALSE)+$G$1 -> 499535.24
C21: Total | D21: =SUM(D3:D19) -> 5057414.4

Sheet SRC-Estimate
A1: Description | B1: Unit | C1: Building Type I | I1: Building Type II
C2: BLDG 1 | I2: BLDG 1
C3: Level 1 | D3: Level 2 | E3: Level 3 | F3: Level 4 | G3: Level 5 | H3: Roof | I3: Level 1 | J3: Level 2 | K3: Level 3 | L3: Level 4 | M3: Level 5 | N3: Roof
A4: Exterior wood stud wall with sheathing | B4: SF | C4: 13143 | D4: 11820 | E4: 13248 | F4: 11460 | G4: 12415 | H4: 1260 | I4: 11100 | J4: 11100 | K4: 11100 | L4: 10920 | M4: 11830 | N4: 1260
A5: House wrap-10'x100' roll size considered | B5: SF | C5: 13143 | D5: 11820 | E5: 13248 | F5: 11460 | G5: 12415 | H5: 1260 | I5: 11100 | J5: 11100 | K5: 11100 | L5: 10920 | M5: 11830 | N5: 1260
A6: Corridor Shear wall sheathing -15/32" plywood | B6: SF | C6: 5775 | D6: 4548 | E6: 4548 | F6: 1380 | G6: 720 | I6: 8145 | J6: 6312 | K6: 4740
A7: Demising Shear wall sheathing -15/32" plywood | B7: SF | C7: 15600 | D7: 13920 | E7: 13920 | F7: 9084 | G7: 360 | I7: 18660 | J7: 15204 | K7: 14532 | L7: 4200
A8: (2) Densglass in btw framing - Stairs | B8: SF | C8: 2448 | D8: 2244 | E8: 2244 | F8: 2244 | G8: 2244 | I8: 2448 | J8: 2244 | K8: 2244 | L8: 2244 | M8: 2244
A9: (2) 1" Gypsum Shaftliners @ Trash Chute | B9: SF | D9: 480 | E9: 480 | F9: 480 | G9: 480 | J9: 480 | K9: 480 | L9: 480 | M9: 480
A10: Unit floor framing : 20" Deep Truss @ 24" OC | B10: SF | D10: 20758 | E10: 20465 | F10: 20465 | G10: 20465 | J10: 20805 | K10: 20805 | L10: 20805 | M10: 20805
A11: Corridor floor framing : 20" Deep Truss @ 24" OC | B11: SF | D11: 2845 | E11: 2845 | F11: 2762 | G11: 2762 | J11: 2645 | K11: 2645 | L11: 2565 | M11: 2565
A12: Balcony floor framing : Pre-fab @ 24"OC | B12: SF | D12: 830 | E12: 1341 | F12: 1341 | G12: 1341 | J12: 1435 | K12: 1435 | L12: 1435 | M12: 1435
A13: L Shaped Balcony floor framing : Pre-fab @ 24"OC | B13: SF | D13: 505 | E13: 505 | F13: 505 | G13: 505 | J13: 182 | K13: 182 | L13: 182 | M13: 182
A14: C Shaped Balcony floor framing : Pre-fab @ 24"OC | B14: SF | D14: 172 | E14: 172 | F14: 172 | G14: 172 | J14: 250 | K14: 250 | L14: 250 | M14: 250
A15: Roof framing : Pre-fab @ 24"OC | B15: SF | H15: 25365 | N15: 25330
A16: Draftstopping @ Unit Floor Truss - Plywood (Assumed) | B16: SF | D16: 1053 | E16: 1053 | F16: 1053 | G16: 1053 | J16: 1053 | K16: 1053 | L16: 1053 | M16: 1053
A17: Draftstopping @ Roof Truss - Plywood (Assumed) | B17: SF | H17: 2085 | N17: 2070
A18: Balcony Doors | B18: EA | D18: 17 | E18: 23 | F18: 23 | G18: 23 | J18: 23 | K18: 23 | L18: 23 | M18: 23
A19: No of Regular balconies | B19: EA | D19: 12 | E19: 18 | F19: 18 | G19: 18 | J19: 20 | K19: 20 | L19: 20 | M19: 20
A20: No of L Shaped Balconies | B20: EA | D20: 3 | E20: 3 | F20: 3 | G20: 3 | J20: 1 | K20: 1 | L20: 1 | M20: 1
A21: No of C Shaped Balconies | B21: EA | D21: 2 | E21: 2 | F21: 2 | G21: 2 | J21: 2 | K21: 2 | L21: 2 | M21: 2
A22: Windows Double | B22: EA | C22: 26 | D22: 43 | E22: 55 | F22: 55 | G22: 58 | I22: 51 | J22: 56 | K22: 58 | L22: 58 | M22: 55
A23: Windows Single | B23: EA | C23: 16 | D23: 24 | E23: 24 | F23: 24 | G23: 25 | I23: 22 | J23: 22 | K23: 22 | L23: 22 | M23: 22
A24: Exterior Entry Doors | B24: EA | C24: 8 | I24: 6
A25: Patio doors | B25: EA | C25: 17 | I25: 22
A26: Wood Column Posts | B26: EA | C26: 3 | D26: 3 | E26: 3 | F26: 3 | I26: 1 | J26: 1 | K26: 1 | L26: 1
A27: Wood Landings | B27: EA | H27: 9 | N27: 7
H28: 343049 | N28: 333088
A30: GSF | B30: SF | C30: 25197 | D30: 25235 | E30: 25334 | F30: 25346 | G30: 25346 | H30: 126458 | I30: 25375 | J30: 25325 | K30: 25325 | L30: 25325 | M30: 25325 | N30: 126675
A32: Total | H32: 469507 | N32: 459763
A34: Their GSF
A35: Difff
O36: Total GSF | P36: 253133
O37: Total with GSF | P37: 929270
O38: Total without GSF | P38: 676137

Sheet SRC-(5) Buyout
A1: Internal Estimate
A2: Description | B2: Company | C2: Type | D2: Unit | E2: Unit cost | F2: Quantity | G2: Total Cost
A3: Layout | C3: Labor | D3: SF | E3: 0.3 | F3: 253133 | G3: 75939.9
A4: Framing | C4: Labor | D4: SF | E4: 1.2 | F4: 253133 | G4: 303759.6
A5: Floor Truss - Unit - Prefabricated | C5: Labor | D5: SF | E5: 1.15 | F5: 165373 | G5: 190178.95
A6: Floor Truss - Corridor - Prefabricated | C6: Labor | D6: SF | E6: 1.15 | F6: 21634 | G6: 24879.1
A7: Balcony - Regular - Hand Framed | C7: Labor | D7: Each | E7: 500 | F7: 146 | G7: 73000
A8: Balcony - L Shaped - Hand Framed | C8: Labor | D8: Each | E8: 600 | F8: 16 | G8: 9600
A9: Balcony - C Shaped - Hand Framed | C9: Labor | D9: Each | E9: 600 | F9: 16 | G9: 9600
A10: Stairs - Landings | C10: Labor | D10: Each | E10: 300 | F10: 16 | G10: 4800
A11: Roof Truss | C11: Labor | D11: SF | E11: 2 | F11: 50695 | G11: 101390
A12: Sheathing - Exterior | C12: Labor | D12: SF | E12: 0.3 | F12: 253133 | G12: 75939.9
A13: Shear Wall - Corridor - 15/32 Plywood | C13: Labor | D13: Sheets | E13: 11 | F13: 1130.25 | G13: 12432.75
A14: Shear Wall - Demising - 15/32 Plywood | C14: Labor | D14: Sheets | E14: 11 | F14: 3296.25 | G14: 36258.75
... A18: Punchout | C18: Labor | D18: SF | E18: 0.25 | F18: 253133 | G18: 63283.25
A19: Nails | B19: Capsol, Inc | C19: Allowance | D19: SF | E19: 0.75 | F19: 253133 | G19: 189849.75
A20: Crane | B20: Capsol, Inc | C20: Allowance | D20: SF | E20: 0.28 | F20: 150000 | G20: 42000
A21: Forklift | B21: Capsol, Inc | C21: Allowance | D21: Months | E21: 8000 | F21: 6 | G21: 48000
A22: Manlift | B22: Capsol, Inc | C22: Allowance | D22: Months | E22: 7000 | F22: 6 | G22: 42000
A23: Fuel | B23: Capsol, Inc | C23: Allowance | D23: Months | E23: 1750 | F23: 6 | G23: 10500
A24: Site Office | B24: Capsol, Inc | C24: Allowance | D24: Months | E24: 1500 | F24: 6 | G24: 9000
A25: Hotels | B25: Capsol, Inc | C25: Allowance | D25: Months | E25: 15000 | F25: 6 | G25: 90000
A26: Site Supervision | B26: Capsol, Inc | C26: Allowance | D26: Month | E26: 18000 | F26: 6 | G26: 108000
C29: Base Cost | D29: 1613831.9
C30: Cost / SF | D30: 6.3754305
C31: Markup | D31: 0.25
C32: Sell Price | D32: 2017289.8
C33: Price / SF | D33: 7.9692881
C35: Base Gross Profit | D35: 403457.96
C36: P/L Margin | D36: 0.2
C37: ROI | D37: 0.25
A42: Buy-Out
A43: Description | B43: Company | C43: Type | D43: Unit | E43: Unit cost | F43: Quantity | G43: Total Cost
A44: Layout | C44: Labor | D44: SF | E44: 0.25 | F44: 253133 | G44: 63283.25
A45: Framing | C45: Labor | D45: SF | E45: 1.1 | F45: 253133 | G45: 278446.3
A46: Floor Truss - Unit - Prefabricated | C46: Labor | D46: SF | E46: 1.1 | F46: 165373 | G46: 181910.3
A47: Floor Truss - Corridor - Prefabricated | C47: Labor | D47: SF | E47: 1.1 | F47: 21634 | G47: 23797.4
A48: Balcony - Regular - Hand Framed | C48: Labor | D48: Each | E48: 500 | F48: 146 | G48: 73000
A49: Balcony - L Shaped - Hand Framed | C49: Labor | D49: Each | E49: 600 | F49: 16 | G49: 9600
A50: Balcony - C Shaped - Hand Framed | C50: Labor | D50: Each | E50: 600 | F50: 16 | G50: 9600
...
